TODO:
Fix Join of output files:
Task 49903c02-1c11-4be1-946b-8566a03dcb51 finished!  Result: COMPLETE - {'stdOut': '/var/archivematica/sharedDirectory/watchedDirectories/quarantined/copy of imalsk-bb9892a9-ab2f-4f24-a21d-c553b7b9c785objects/WFPC01.GIF.mp3\nNothing to do\n', 'exitCode': 0, 'stdError': ''}
writing to: /var/archivematica/sharedDirectory/watchedDirectories/quarantined/copy of imalsk-bb9892a9-ab2f-4f24-a21d-c553b7b9c785logs/extraction.log
I/O error(2): No such file or directory

unquarantine/quarantine events



UPDATE Files SET currentPath='%SIPDirectory%objects/metadata/submissionDocumentation/Accession_Form_Samples.pdf' WHERE fileUUID='893440b1-163e-4579-aa0b-94d5d6350a35'


removedTime         
Rename & file UUIDs

| enteredSystem 


in sanitize object names:
eventDetailText= "program=\"sanitizeNames\"; version=\"" + version + "\""
IS NOT USED

... create event looks wrong

<<< Verify checksums generated on ingest >>>
<<< Remove logs where information is now in METS >>>
<<< Add Dublin Core to METS >>>
could be part of generate mets.

ERROR when left alone for period of time:
/var/archivematica/sharedDirectory/watchedDirectories/receiveSIP/copy of imalsk/ ('%watchDirectoryPath%receiveSIP', 9L, 1)
SELECT sipUUID FROM SIPs WHERE currentPath = '%sharedPath%watchedDirectories/receiveSIP/copy of imalsk/'
Exception in thread Thread-33:
Traceback (most recent call last):
  File "/usr/lib/python2.6/threading.py", line 532, in __bootstrap_inner
    self.run()
  File "/usr/lib/python2.6/threading.py", line 736, in run
    self.function(*self.args, **self.kwargs)
  File "/home/joseph/archivematica/src/MCPServer/lib/watchDirectory.py", line 67, in timerExpired
    self.watchDirectoryProcessEvent.process_IN_MOVED_TO(self.event)
  File "/home/joseph/archivematica/src/MCPServer/lib/watchDirectory.py", line 113, in process_IN_MOVED_TO
    self.callBackFunction(path, self.config)
  File "./archivematicaMCP.py", line 126, in createUnitAndJobChain
    UUID = findOrCreateSipInDB(path)
  File "./archivematicaMCP.py", line 95, in findOrCreateSipInDB
    c, sqlLock = databaseInterface.querySQL(sql)
  File "/usr/lib/archivematica/archivematicaCommon/databaseInterface.py", line 92, in querySQL
    c=database.cursor()
AttributeError: cursor


Quarantine and unquarantine events.

Add checksums/checksum events.
Verify above checksums.

Removing files not accounted for.

Naming needs to be reviewed.
Some "appraisal steps" are the same as their action ie. upload DIP.



